Workbook

Sheet sources_consumption
A1: Year | B1: Good | C1: Amount | D1: Amount (oz per 10,000 per simumonth) | E1: Link
A2: 1800 | B2: meat | C2: 3.5 oz/man/day | D2: =3.5*10000*6.4 / 8 -> 28000 | E2: 9.3. Consumption of Meat – The Industrial Revolution in England was not All Bad
B3: flour | C3: 1.2 lb/man/day | D3: =(16*1.2)*6.4*10000/8 -> 153600 | E3: 9.1. Consumption of Cereals – The Industrial Revolution in England was not All Bad
B4: fruit | C4: See note 1 | D4: =D5/2.125 -> 9959.5294
B5: vegetables | C5: 60 cal potato/man/day | D5: =2.6455*6.4*10000/8 -> 21164 | E5: 9.3A. Consumption of Other Foods – The Industrial Revolution in England was not All Bad
B6: milk | C6: 0.15 pint/person/day | D6: =0.08523922 * 10000 * 6.4 / 8 -> 681.91376 | E6: 9.3A. Consumption of Other Foods – The Industrial Revolution in England was not All Bad
A7: 1850 | B7: milk | C7: 0.11 pint/person/day | D7: =0.06250876 * 10000 * 6.4 / 8 -> 500.07008 | E7: 9.3A. Consumption of Other Foods – The Industrial Revolution in England was not All Bad
B8: vegetables | C8: 175 cal potato/man/day | D8: =7.93*6.4*10000/8 -> 63440 | E8: 9.3A. Consumption of Other Foods – The Industrial Revolution in England was not All Bad
A9: 1880 | B9: meat | C9: 5.4 oz/man/day | D9: =5.4 * 10000 *6.4 / 8 -> 43200 | E9: 9.3. Consumption of Meat – The Industrial Revolution in England was not All Bad
B10: flour | C10: 1.0 lb/man/day | D10: =(16*1)*6.4*10000/8 -> 128000 | E10: 9.1. Consumption of Cereals – The Industrial Revolution in England was not All Bad
B11: fruit | C11: ~85 cal fruit/man/day (see note 1) | D11: =D8/2.125 -> 29854.118
A12: 1909-13 | B12: meat | C12: 41.3 oz/man/week | D12: =(41.3/7)*10000*6.4/8 -> 47200 | E12: The_Urban_Working_-_Class_Household_Diet_1940-1949.pdf
B13: fish | C13: 12.6 oz/man/week | D13: =(12.6/7)*10000*6.4/8*(5.35/(5.35+D52)) -> 11246.715 | E13: Note: subtracted estimated canned fish portion
B14: flour | C14: 71.2 oz/man/week | D14: =(71.2/7)*10000*6.4/8 -> 81371.429
B15: vegetables | C15: 97 oz/man/week | D15: =(97/7)*10000*6.4/8 -> 110857.14
B16: fruit | C16: 19 oz/man/week | D16: =(19/7)*10000*6.4/8 -> 21714.286
B17: milk | C17: 3.5 pints/man/week | D17: =(1.98891525/7)*10000*6.4/8 -> 2273.046
A18: 1934-35 | B18: meat | C18: 45 oz/man/week | D18: =(45/7)*10000*6.4/8 -> 51428.571 | E18: The_Urban_Working_-_Class_Household_Diet_1940-1949.pdf
B19: fish | C19: 13.9 oz/man/week | D19: =((13.9/7)*10000*6.4/8)*(5.35/(5.35+D52)) -> 12407.091 | E19: Note: subtracted estimated canned fish portion
B20: flour | C20: 64.6 oz/man/week | D20: =(64.6/7)*10000*6.4/8 -> 73828.571
B21: vegetables | C21: 103.5 oz/man/week | D21: =(103.5/7)*10000*6.4/8 -> 118285.71
B22: fruit | C22: 35.7 oz/man/week | D22: =(35.7/7)*10000*6.4/8 -> 40800
B23: milk | C23: 3.3 pints/man/week | D23: =(1.87526295/7)*10000*6.4/8 -> 2143.1577
A24: 1970 | B24: meat | C24: 39.53 oz/man/week | D24: =(39.53 / 7) *10000*6.4/8 -> 45177.143 | E24: https://assets.publishing.service.gov.uk/media/5a7f0f7740f0b62305b84d2e/Domestic_Food_Consumption_and_Expenditure_1970_and_1971.pdf
B25: fish | C25: 5.35 oz/man/week | D25: =(5.35/7)*6.4*10000/8 -> 6114.2857
B26: flour | C26: 63.19 oz/man/week | D26: =(63.19/7)*10000*6.4/8 -> 72217.143
B27: vegetables | C27: 87.55 oz/man/week | D27: =(87.55/7)*10000*6.4/8 -> 100057.14
B28: fresh fruit | C28: 23.14 oz/man/week | D28: =(23.14/7)*6.4*10000/8 -> 26445.714
B29: milk | C29: 5.08 pint/man/week | D29: =(2.88676842 / 7) * 10000 * 6.4 / 8 -> 3299.1639
B30: canned food | D30: =(D54/7)*10000*6.4/8 -> 17588.571
A31: 2000 | B31: meat | C31: 1016 g/man/week | D31: =((1016*0.03527396)/7)*6.4*10000/8 -> 40958.107 | E31: Microsoft Word - oct interim report.doc
B32: fish | C32: 163 g/man/week | D32: =(163/1016)*D31 -> 6571.0348
B33: flour | C33: 1790 g/man/week | D33: =(1790/1016)*D31 -> 72160.444
B34: vegetables | C34: 2140 g/man/week | D34: =(2140/1016)*D31 -> 86270.028
B35: fresh fruit | C35: 761 g/man/week | D35: =(761/1016)*D31 -> 30678.267
B36: milk | C36: 2156 ml/man/week | D36: =(2.156/7)*10000*6.4/8 -> 2464
B37: canned food | D37: =((B54*0.03527396) / 7)*10000*6.4/8 -> 42852.822
A38: ASSUMPTIONS
A39: 1 | B39: flour consumption = all grain products (bread, pastry, flour) consumption (e.g. 'cereals' category)
A40: 2 | B40: milk consumption = all dairy products (cheese, cream, etc) until modern processed dairy becomes a thing (1970 onwards - exclude cheese), in liters
...

Sheet sources_distweight
A1: Year | B1: Store type | C1: Ingame industry | D1: Number of stores | E1: Floor area (m2) | F1: Floor area (inferred) | G1: Canadian population | H1: Relative footprint (pop. Adj)
A2: 1933
A3: 1950 | B3: Grocery stores | D3: 230 | G3: 14009400
B4: Combination stores | D4: 879 | G4: 14009400
B5: Bakery | D5: 162 | G5: 14009400
B6: Meat markets | D6: 53 | G6: 14009400
B7: Variety stores | D7: 560 | G7: 14009400
B8: Clothing stores (minus shoes) | C8: ClothesShop1945 | D8: =158+142+458 -> 758 | F8: =(E$27/D$27)*D8 -> 343100.99 | G8: 14009400 | H8: =((F8/E$31)*H$31)*(G$31/G8) -> 14.902338
B9: Hardware stores | D9: 49 | G9: 14009400
B10: Furniture stores | D10: 184 | G10: 14009400
B11: Drug stores | D11: 320 | G11: 14009400
A12: 1960 | B12: Grocery & combination stores | C12: Supermarket1950 | D12: 1494 | F12: =(E$24/D$24)*D12 -> 124689.4 | G12: 18238200 | H12: =(F12/E$31)*H$31*(G$31/G20) -> 4.1600597
G13: 18238200
B14: Bakery | D14: 250 | F14: =(E$24/D$24)*D14 -> 20865.027 | G14: 18238200 | H14: =(F14/E$31)*H$31*(G$31/G20) -> 0.69612779
B15: Meat market | C15: Butchery1945 | D15: 50 | F15: =(E38/D38)*D15 -> 14632.634 | G15: 18238200 | H15: =(F15/E$31)*H$31 -> 0.29385029
B16: Variety stores | D16: 780 | G16: 18238200 | H16: =(F16/E$31)*H$31 -> 0
B17: Clothing stores | D17: =222+707+214 -> 1143 | F17: =(E$27/D$27)*D17 -> 517367.32 | G17: 18238200 | H17: =(F17/E$31)*H$31*(G$31/G20) -> 17.261121
B18: Hardware stores | D18: 169 | G18: 18238200 | H18: =(F18/E$31)*H$31 -> 0
B19: Furniture stores | D19: 212 | F19: =(E28/D28)*D19 -> #DIV/0! | G19: 18238200 | H19: =(F19/E$31)*H$31 -> #DIV/0!
B20: Drug stores | D20: 383 | F20: =(E25/D25)*D20 -> 38103.151 | G20: 18238200 | H20: =(((F20/E$31)*H$31)*(G$31/G20)) -> 1.2712498
A21: 1980 | B21: Supermarket | C21: Supermarket1960 | D21: 1705 | E21: =36304160/C42 -> 3372766.8 | G21: 24819900 | H21: =(E21/E$31)*H$31*(G$31/G29) -> 82.687198
B22: Meat market | D22: 28 | F22: =(E24/D24)*D22 -> 2336.8831 | G22: 24819900
B23: Grocery store | G23: 24819900
B24: Bakery | D24: 28 | E24: =25154/C42 -> 2336.8831 | G24: 24819900 | H24: =(E24/E$31)*H$31*(G$31/G29) -> 0.057291335
B25: Drug stores | C25: Chemist1955 | D25: 531 | E25: =568626/C42 -> 52827.084 | G25: 24819900 | H25: =(E25/E$31)*H$31*(G$31/G29)*(G$31/G29) -> 1.5810912
B26: General stores | C26: Convenience1975 | D26: 222 | E26: =2562641/C42 -> 238077.14 | G26: 24819900 | H26: =(E26/E$31)*H$31*(G$31/G29) -> 5.8367307
B27: Clothing stores (minus shoes) | C27: ClothesShop1960 | D27: =683+1489+117+887+130 -> 3306 | E27: =(4194002+4284894+294398+6749058+585057)/C42 -> 1496427.3 | G27: 24819900 | H27: =(E27/E$31)*H$31*(G$31/G29) -> 36.686609
B28: Furniture + appliance stores | G28: 24819900
B29: Book & stationery stores | C29: Bookshop1970 | D29: 464 | E29: =194862/C42 -> 18103.272 | G29: 24819900 | H29: =(E29/E$31)*H$31*(G$31/G29) -> 0.44382222
B30: Department stores | C30: DepartmentStore1960 | D30: =C50+C54 -> 752 | E30: =C63 -> 2591920 | G30: 24819900 | H30: =(E30/E$31)*H$31*(G$31/G30) -> 63.543854
A31: 1998 | B31: Supermarket | C31: Supermarket1980 | D31: 1481 | E31: 4979622 | G31: 30300400 | H31: 100
B32: Grocery store | D32: 1693 | E32: 366963 | G32: 30300400 | H32: =(E32/E31)*H31 -> 7.3692943
B33: Pharmacies | C33: Chemist1975 | D33: 827 | E33: 463960 | G33: 30300400 | H33: =(E33/E$31)*H$31 -> 9.3171731
B34: Clothing stores (minus shoes) | C34: ClothesShop1990 | D34: =821+3613+370+2774 -> 7578 | E34: =265751+753638+85192+1627134 -> 2731715 | G34: 30300400 | H34: =(E34/E$31)*H$31 -> 54.857879
B35: Furniture + appliance stores | G35: 30300400
B36: Book & stationery stores | C36: N/A? | D36: 858 | E36: 325108 | G36: 30300400 | H36: =(E36/E$31)*H$31 -> 6.5287686
B37: Department stores | C37: DepartmentStore1990 | D37: 810 | E37: =F63 -> 7559015.1 | G37: 30300400 | H37: =(E37/E$31)*H$31 -> 151.79897
B38: Other food stores (butcher, etc) | D38: 262 | E38: 76675 | G38: 30300400 | H38: =(E38/E$31)*H$31 -> 1.5397755
A39: ASSUMPTIONS
A40: 1 | B40: Canadian data will be used, as it is readily available and detailed. It is assumed that relative changes in number and size of stores over time in Canada are mirrored in the UK.
...

Sheet dist_calculations
A1: Industry | B1: Old distweight | C1: Footprint | D1: Relative floor area | E1: New distweight | F1: Number of stores UK today | G1: Number of stores/industry | J1: Note
A2: Greengrocers1820 | E2: 8 | J2: Made-up
A3: Greenfrocers1840 | E3: 16 | J3: Made-up
A4: Greengrocers1910 | E4: 24 | J4: Made-up
A5: Greengrocers1945 | E5: 7 | J5: Made-up
A6: Fishmongers1820 | B6: 27 | E6: 54 | J6: Made-up
A7: Fishmongers1840 | B7: 27 | E7: 54 | J7: Made-up
A8: Fishmongers1910 | B8: 21 | E8: 52 | J8: Made-up
A9: Fishmongers1945 | B9: 12 | E9: 20 | J9: Made-up
A10: Grocer1810 | E10: 8 | J10: Made-up
A11: Grocer1860 | E11: 16 | J11: Made-up
A12: Grocer1900 | E12: 20 | J12: Made-up
A13: Grocer1945 | E13: 20 | J13: Made-up
A14: Market1750 | B14: 75 | E14: 50
A15: Market1840 | B15: 45 | E15: 45
A16: Market1910 | B16: 10 | E16: 14
A17: Market1945 | B17: 4 | E17: 6
A19: ClothesShop1945 | C19: 1 | D19: =sources_distweight!H8 -> 14.902338 | E19: =MAX(ROUND((D19/D$30)*(C$30/C19)*E$30,0),1) -> 27
A20: Bakery1945 | C20: 1
A21: Butchery1945 | C21: 1 | D21: =sources_distweight!H15 -> 0.29385029 | E21: =MAX(ROUND((D21/D$30)*(C$30/C21)*E$30,0),1) -> 1
A22: Supermarket1950 | C22: 1 | D22: =sources_distweight!H12 -> 4.1600597 | E22: =MAX(ROUND((D22/D$30)*(C$30/C22)*E$30,0),1) -> 8
A23: Chemist1955 | C23: 1 | D23: =sources_distweight!H25 -> 1.5810912 | E23: =MAX(ROUND((D23/D$30)*(C$30/C23)*E$30,0),1) -> 3
A24: Supermarket1960 | C24: 4 | D24: =sources_distweight!H21 -> 82.687198 | E24: =MAX(ROUND((D24/D$30)*(C$30/C24)*E$30,0),1) -> 38 | G24: 8.33333
A25: ClothesShop1960 | C25: 1 | D25: =sources_distweight!H27 -> 36.686609 | E25: =MAX(ROUND((D25/D$30)*(C$30/C25)*E$30,0),1) -> 67
A26: Convenience1975 | C26: 1 | D26: =sources_distweight!H26 -> 5.8367307 | E26: =MAX(ROUND((D26/D$30)*(C$30/C26)*E$30,0),1) -> 11
A27: Chemist1975 | C27: 1 | D27: =sources_distweight!H33 -> 9.3171731 | E27: =MAX(ROUND((D27/D$30)*(C$30/C27)*E$30,0),1) -> 17
A28: SupermarketSmall1990 | C28: 4 | D28: =sources_distweight!H31 *(50/150) -> 33.333333 | E28: =MAX(ROUND((D28/D$30)*(C$30/C28)*E$30,0),1) -> 15 | F28: 23800 | G28: =(25/12)*4 -> 8.3333333
A29: Supermarket1980 | C29: 12 | D29: =sources_distweight!H31 *(100/150) -> 66.666667 | E29: =MAX(ROUND((D29/D$30)*(C$30/C29)*E$30,0),1) -> 10 | F29: 23800 | G29: 25
A30: ClothesShop1990 | C30: 1 | D30: =sources_distweight!H34 -> 54.857879 | E30: 100
A31: DepartmentStore1990 | C31: 6 | D31: =sources_distweight!H37 -> 151.79897 | E31: =MAX(ROUND((D31/D$30)*(C$30/C31)*E$30,0),1) -> 46

Sheet food summary
A1: Industry | B1: Average change | C1: Consumption (current) | K1: Consumption (modified) | S1: Consumption change
C2: meat | D2: milk | E2: fish | F2: flour | G2: vegetables | H2: fruit | I2: canned | J2: beer | K2: meat | L2: milk | M2: fish | N2: flour | O2: vegetables | P2: fruit | Q2: canned | R2: beer | S2: meat | T2: milk | U2: fish | V2: flour | W2: vegetables | X2: fruit | Y2: canned | Z2: beer
A3: Market1750 | B3: =SUMPRODUCT(S3:X3,G38:L38)/SUM(G38:L38) -> 1.6790786 | C3: =meat!H2 -> 48 | E3: =fish!H2 -> 15 | G3: =vegetables!H2 -> 93 | H3: =fruit!H2 -> 48 | K3: =meat!I2 -> 72 | M3: =fish!I2 -> 197.66064 | O3: =vegetables!I2 -> 40.147228 | P3: =fruit!I2 -> 32.724162 | S3: =K3/C3 -> 1.5 | U3: =M3/E3 -> 13.177376 | W3: =O3/G3 -> 0.43169063 | X3: =P3/H3 -> 0.68175337
A4: Dairy1750 | B4: =SUMPRODUCT(S4:X4,G39:L39)/SUM(G39:L39) -> 0.2324706 | D4: =milk!H2 -> 210 | L4: =milk!I2 -> 48.818826 | T4: =L4/D4 -> 0.2324706
A5: Grocer1810 | B5: =SUMPRODUCT(S5:Z5,G40:N40)/SUM(G40:N40) -> 1.2539645 | I5: =canned!H2 -> 10.56 | Q5: =canned!I2 -> 13.241865 | Y5: =Q5/I5 -> 1.2539645
A6: Fishmongers1820 | B6: =SUMPRODUCT(S6:Z6,G41:N41)/SUM(G41:N41) -> 4.4903526 | E6: =fish!H3 -> 54 | M6: =fish!I3 -> 242.47904 | U6: =M6/E6 -> 4.4903526
A7: Greengrocers1820 | B7: =SUMPRODUCT(S7:X7,G42:L42)/SUM(G42:L42) -> 0.82047562 | G7: =vegetables!H3 -> 27 | H7: =fruit!H3 -> 27 | O7: =vegetables!I3 -> 23.700316 | P7: =fruit!I3 -> 20.605367 | W7: =O7/G7 -> 0.87778949 | X7: =P7/H7 -> 0.76316175
A8: Bakery1750 | B8: =AVERAGE(S8:V8) -> 3.3525293 | F8: =flour!H2 -> 32 | N8: =flour!I2 -> 107.28094 | V8: =N8/F8 -> 3.3525293
A9: Butchery1820 | B9: =AVERAGE(S9:V9) -> 0.625 | C9: =meat!H3 -> 24 | K9: =meat!I3 -> 15 | S9: =K9/C9 -> 0.625
A10: Market1840 | B10: =SUMPRODUCT(S10:X10,G45:L45)/SUM(G45:L45) -> 1.0585945 | C10: =meat!H4 -> 57.6 | E10: =fish!H4 -> 18 | G10: =vegetables!H4 -> 111.6 | H10: =fruit!H4 -> 57.6 | K10: =meat!I4 -> 54 | M10: =fish!I4 -> 36.436076 | O10: =vegetables!I4 -> 126.92716 | P10: =fruit!I4 -> 41.780705 | S10: =K10/C10 -> 0.9375 | U10: =M10/E10 -> 2.0242264 | W10: =O10/G10 -> 1.1373402 | X10: =P10/H10 -> 0.72535946
A11: Dairy1840 | B11: =SUMPRODUCT(S11:Z11,G47:N47)/SUM(G47:N47) -> 0.42232161 | D11: =milk!H3 -> 210 | L11: =milk!I3 -> 88.687537 | T11: =L11/D11 -> 0.42232161
A12: Grocer1860 | B12: =SUMPRODUCT(S12:Z12,G46:N46)/SUM(G46:N46) -> 1.0031716 | I12: =canned!H3 -> 36.96 | Q12: =canned!I3 -> 37.077222 | Y12: =Q12/I12 -> 1.0031716
A13: Fishmongers1840 | B13: =SUMPRODUCT(S13:Z13,G48:N48)/SUM(G48:N48) -> 2.0242264 | E13: =fish!H5 -> 135 | M13: =fish!I5 -> 273.27057 | U13: =M13/E13 -> 2.0242264
A14: Greengrocers1840 | B14: =SUMPRODUCT(S14:X14,G49:L49)/SUM(G49:L49) -> 0.90192263 | G14: =vegetables!H5 -> 54 | H14: =fruit!H5 -> 72 | O14: =vegetables!I5 -> 61.41637 | P14: =fruit!I5 -> 52.225881 | W14: =O14/G14 -> 1.1373402 | X14: =P14/H14 -> 0.72535946
A15: Bakery1840 | B15: =AVERAGE(S15:V15) -> 1.5086382 | F15: =flour!H3 -> 60 | N15: =flour!I3 -> 90.51829 | V15: =N15/F15 -> 1.5086382
A16: Butchery1840 | B16: =AVERAGE(S16:V16) -> 0.93333333 | C16: =meat!H5 -> 60 | K16: =meat!I5 -> 56 | S16: =K16/C16 -> 0.93333333
A17: Market1910 | B17: =SUMPRODUCT(S17:X17,G52:L52)/SUM(G52:L52) -> 1.8132189 | C17: =meat!H6 -> 12.8 | E17: =fish!H6 -> 4 | G17: =vegetables!H6 -> 24.8 | H17: =fruit!H6 -> 12.8 | K17: =meat!I6 -> 16.873957 | M17: =fish!I6 -> 7.2688938 | O17: =vegetables!I6 -> 62.016283 | P17: =fruit!I6 -> 12.479976 | S17: =K17/C17 -> 1.3182779 | U17: =M17/E17 -> 1.8172234 | W17: =O17/G17 -> 2.5006566 | X17: =P17/H17 -> 0.9749981
A18: Dairy1910 | B18: =SUMPRODUCT(S18:Z18,G54:N54)/SUM(G54:N54) -> 0.69348567 | D18: =milk!H4 -> 225 | L18: =milk!I4 -> 156.03428 | T18: =L18/D18 -> 0.69348567
A19: Grocer1900 | B19: =SUMPRODUCT(S19:Z19,G53:N53)/SUM(G53:N53) -> 0.50381506 | I19: =canned!H4 -> 118.8 | Q19: =canned!I4 -> 59.85323 | Y19: =Q19/I19 -> 0.50381506
A20: Fishmongers1910 | B20: =SUMPRODUCT(S20:Z20,G55:N55)/SUM(G55:N55) -> 1.8172234 | E20: =fish!H7 -> 210 | M20: =fish!I7 -> 381.61692 | U20: =M20/E20 -> 1.8172234
A21: Greengrocers1910 | B21: =SUMPRODUCT(S21:Z21,G56:N56)/SUM(G56:N56) -> 1.5870886 | G21: =vegetables!H7 -> 80.4 | H21: =fruit!H7 -> 120 | O21: =vegetables!I7 -> 201.05279 | P21: =fruit!I7 -> 116.99977 | W21: =O21/G21 -> 2.5006566 | X21: =P21/H21 -> 0.9749981
A22: Bakery1910 | B22: =SUMPRODUCT(S22:Z22,G57:N57)/SUM(G57:N57) -> 0.65481736 | F22: =flour!H4 -> 81 | N22: =flour!I4 -> 53.040206 | V22: =N22/F22 -> 0.65481736
A23: Butchery1910 | B23: =SUMPRODUCT(S23:Z23,G58:N58)/SUM(G58:N58) -> 1.3182779 | C23: =meat!H7 -> 81 | K23: =meat!I7 -> 106.78051 | S23: =K23/C23 -> 1.3182779
A24: Market1945 | B24: =SUMPRODUCT(S24:Z24,G59:N59)/SUM(G59:N59) -> 1.8680267 | C24: =meat!H8 -> 7.68 | E24: =fish!H8 -> 2.4 | G24: =vegetables!H8 -> 14.88 | H24: =fruit!H8 -> 7.68 | K24: =meat!I8 -> 13.498278 | M24: =fish!I8 -> 2.881003 | O24: =vegetables!I8 -> 37.439898 | P24: =fruit!I8 -> 7.1532111 | S24: =K24/C24 -> 1.7575882 | U24: =M24/E24 -> 1.2004179 | W24: =O24/G24 -> 2.5161222 | X24: =P24/H24 -> 0.9314077
A25: Grocer1945 | B25: =SUMPRODUCT(S25:Z25,G60:N60)/SUM(G60:N60) -> 1.0459609 | I25: =canned!H5 -> 63.36 | Q25: =canned!I5 -> 66.272082 | Y25: =Q25/I25 -> 1.0459609
A26: Fishmongers1945 | B26: =SUMPRODUCT(S26:Z26,G61:N61)/SUM(G61:N61) -> 0.95694437 | E26: =fish!H9 -> 180 | M26: =fish!I9 -> 172.24999 | U26: =M26/E26 -> 0.95694437
A27: Greengrocers1945 | B27: =SUMPRODUCT(S27:X27,G62:L62)/SUM(G62:L62) -> 0.64380485 | G27: =vegetables!H9 -> 60.3 | H27: =fruit!H9 -> 90 | O27: =vegetables!I9 -> 53.703468 | P27: =fruit!I9 -> 43.060401 | W27: =O27/G27 -> 0.89060478 | X27: =P27/H27 -> 0.4784489
A28: Bakery1945 | B28: =AVERAGE(S28:V28) -> 0.50238688 | F28: =flour!H5 -> 96 | N28: =flour!I5 -> 48.22914 | V28: =N28/F28 -> 0.50238688
A29: Butchery1945 | B29: =AVERAGE(S29:V29) -> 1.7575882 | C29: =meat!H9 -> 48 | K29: =meat!I9 -> 84.364236 | S29: =K29/C29 -> 1.7575882
A30: Supermarket1950 | B30: =SUMPRODUCT(S30:Z30,G65:N65)/SUM(G65:N65) -> 1.0265978 | C30: =meat!H10 -> 10.08 | D30: =milk!H5 -> 7.84 | E30: =fish!H10 -> 3.15 | F30: =flour!H6 -> 5.04 | G30: =vegetables!H10 -> 19.53 | H30: =fruit!H10 -> 10.08 | I30: =canned!H6 -> 12.6 | K30: =meat!I10 -> 7.4279381 | L30: =milk!I5 -> 20.692731 | M30: =fish!I10 -> 3.2657655 | N30: =flour!I6 -> 1.7748181 | O30: =vegetables!I10 -> 17.393511 | P30: =fruit!I10 -> 4.8227649 | Q30: =canned!I6 -> 13.179107 | S30: =K30/C30 -> 0.73689862 | T30: =L30/D30 -> 2.639379 | U30: =M30/E30 -> 1.0367509 | V30: =N30/F30 -> 0.35214644 | W30: =O30/G30 -> 0.89060478 | X30: =P30/H30 -> 0.4784489 | Y30: =Q30/I30 -> 1.0459609
A31: Supermarket1960 | B31: =SUMPRODUCT(S31:Z31,G66:N66)/SUM(G66:N66) -> 1.2388153 | C31: =meat!H11 -> 85.12 | D31: =milk!H6 -> 74.48 | E31: =fish!H11 -> 26.6 | F31: =flour!H7 -> 42.56 | G31: =vegetables!H11 -> 164.92 | H31: =fruit!H11 -> 85.12 | I31: =canned!H7 -> 106.4 | K31: =meat!I11 -> 97.863609 | L31: =milk!I6 -> 217.80309 | M31: =fish!I11 -> 25.268282 | N31: =flour!I7 -> 45.093036 | O31: =vegetables!I11 -> 197.87686 | P31: =fruit!I11 -> 79.765013 | Q31: =canned!I7 -> 61.284797 | S31: =K31/C31 -> 1.1497134 | T31: =L31/D31 -> 2.9243164 | U31: =M31/E31 -> 0.94993543 | V31: =N31/F31 -> 1.0595168 | W31: =O31/G31 -> 1.1998354 | X31: =P31/H31 -> 0.93708897 | Y31: =Q31/I31 -> 0.57598494
A32: Convenience1975 | B32: =SUMPRODUCT(S32:Z32,G67:N67)/SUM(G67:N67) -> 0.94852261 | D32: =milk!H7 -> 2.88 | I32: =canned!H8 -> 22.88 | L32: =milk!I7 -> 3.0898641 | Q32: =canned!I8 -> 19.732543 | T32: =L32/D32 -> 1.0728695 | Y32: =Q32/I32 -> 0.86243632
A33: SupermarketSmall1990 | B33: =SUMPRODUCT(S33:Z33,G68:N68)/SUM(G68:N68) -> 1 | C33: =meat!H12 -> 33.6 | D33: =milk!H8 -> 58.8 | E33: =fish!H12 -> 10.5 | F33: =flour!H8 -> 16.8 | G33: =vegetables!H12 -> 65.1 | H33: =fruit!H12 -> 33.6 | I33: =canned!H11 -> 42 | K33: =meat!I12 -> 33.6 | L33: =milk!I8 -> 58.8 | M33: =fish!I12 -> 10.5 | N33: =flour!I8 -> 16.8 | O33: =vegetables!I12 -> 65.1 | P33: =fruit!I12 -> 33.6 | Q33: =canned!I11 -> 42 | S33: =K33/C33 -> 1 | T33: =L33/D33 -> 1 | U33: =M33/E33 -> 1 | V33: =N33/F33 -> 1 | W33: =O33/G33 -> 1 | X33: =P33/H33 -> 1 | Y33: =Q33/I33 -> 1
A34: Supermarket1980 | B34: =SUMPRODUCT(S34:Z34,G69:N69)/SUM(G69:N69) -> 1.0009425 | C34: =meat!H13 -> 67.2 | D34: =milk!H9 -> 117.6 | E34: =fish!H13 -> 21 | F34: =flour!H9 -> 33.6 | G34: =vegetables!H13 -> 130.2 | H34: =fruit!H13 -> 67.2 | I34: =canned!H10 -> 84 | K34: =meat!I13 -> 67.661478 | L34: =milk!I9 -> 120.25734 | M34: =fish!I13 -> 20.902687 | N34: =flour!I9 -> 33.60176 | O34: =vegetables!I13 -> 131.58718 | P34: =fruit!I13 -> 66.581913 | Q34: =canned!I10 -> 80.698472 | S34: =K34/C34 -> 1.0068672 | T34: =L34/D34 -> 1.0225964 | U34: =M34/E34 -> 0.99536604 | V34: =N34/F34 -> 1.0000524 | W34: =O34/G34 -> 1.0106542 | X34: =P34/H34 -> 0.99080228 | Y34: =Q34/I34 -> 0.96069609
A36: Industry | B36: Dist.weight | C36: New dist.weight | D36: Productivity | E36: New Productivity | G36: InputFactor | O36: New InputFactor
G37: meat | H37: milk | I37: fish | J37: flour | K37: vegetables | L37: fruit | M37: canned | N37: beer | O37: meat | P37: milk | Q37: fish | R37: flour | S37: vegetables | T37: fruit | U37: canned | V37: beer
A38: Market1750 | B38: 75 | C38: =dist_calculations!E14 -> 50 | D38: 4 | E38: =ROUND((D38*B3)/(C38/B38),0) -> 10 | G38: 16 | I38: 5 | K38: 31 | L38: 16 | O38: =ROUND((S3/($E38/$D38))*G38,0) -> 10 | Q38: =ROUND((U3/($E38/$D38))*I38,0) -> 26 | S38: =ROUND((W3/($E38/$D38))*K38,0) -> 5 | T38: =ROUND((X3/($E38/$D38))*L38,0) -> 4
A39: Dairy1750 | B39: 42 | C39: 8 | D39: 5 | E39: =ROUND((D39*B4)/(C39/B39),0) -> 6 | H39: 100 | P39: =ROUND((T4/(($E39/$D39)*($C39/$B39)))*H39,0) -> 102
A40: Grocer1810 | B40: 8 | C40: =dist_calculations!E10 -> 8 | D40: 4 | E40: =ROUND((D40*B5)/(C40/B40),0) -> 5 | M40: 33 | U40: =ROUND((Y5/(($E40/$D40)*($C40/$B40)))*M40,0) -> 33
A41: Fishmongers1820 | B41: 27 | C41: =dist_calculations!E6 -> 54 | D41: 2 | E41: =ROUND((D41*B6)/(C41/B41),0) -> 4 | I41: 100 | Q41: =ROUND((U6/(($E41/$D41)*($C41/$B41)))*I41,0) -> 112
...

Sheet meat
A1: Industry | B1: Start year | C1: End year | D1: Midpoint | E1: new distweight | F1: productivity | G1: InputFactor | H1: eff. Consumption | I1: Modified consumption
A2: Market1750 | B2: 1750 | C2: 1840 | D2: =(B2+C2)/2 -> 1795 | E2: 75 | F2: 4 | G2: 16 | H2: =E2*F2*G2/100 -> 48 | I2: 72
A3: Butchery1820 | B3: 1820 | C3: 1840 | D3: =(B3+C3)/2 -> 1830 | E3: 24 | F3: 1 | G3: 100 | H3: =E3*F3*G3/100 -> 24 | I3: 15
A4: Market1840 | B4: 1840 | C4: 1910 | D4: =(B4+C4)/2 -> 1875 | E4: 45 | F4: 8 | G4: 16 | H4: =E4*F4*G4/100 -> 57.6 | I4: 54
A5: Butchery1840 | B5: 1840 | C5: 1910 | D5: =(B5+C5)/2 -> 1875 | E5: 30 | F5: 2 | G5: 100 | H5: =E5*F5*G5/100 -> 60 | I5: 56
A6: Market1910 | B6: 1910 | C6: 1945 | D6: =(B6+C6)/2 -> 1927.5 | E6: 10 | F6: 8 | G6: 16 | H6: =E6*F6*G6/100 -> 12.8 | I6: =(G$25/C$25)*H6 -> 16.873957
A7: Butchery1910 | B7: 1910 | C7: 1945 | D7: =(B7+C7)/2 -> 1927.5 | E7: 27 | F7: 3 | G7: 100 | H7: =E7*F7*G7/100 -> 81 | I7: =(G$25/C$25)*H7 -> 106.78051
A8: Market1945 | B8: 1945 | C8: 1975 | D8: =(B8+C8)/2 -> 1960 | E8: 4 | F8: 12 | G8: 16 | H8: =E8*F8*G8/100 -> 7.68 | I8: =(G$29/C$29)*H8 -> 13.498278
A9: Butchery1945 | B9: 1945 | C9: 1975 | D9: =(B9+C9)/2 -> 1960 | E9: 12 | F9: 4 | G9: 100 | H9: =E9*F9*G9/100 -> 48 | I9: =(G$29/C$29)*H9 -> 84.364236
A10: Supermarket1950 | B10: 1950 | C10: 1982 | D10: =(B10+C10)/2 -> 1966 | E10: 9 | F10: 7 | G10: 16 | H10: =E10*F10*G10/100 -> 10.08 | I10: =(G$31/C$31)*H10 -> 7.4279381
A11: Supermarket1960 | B11: 1960 | C11: 1990 | D11: =(B11+C11)/2 -> 1975 | E11: =dist_calculations!E$24 -> 38 | F11: 14 | G11: 16 | H11: =E11*F11*G11/100 -> 85.12 | I11: =(G$32/C$32)*H11 -> 97.863609
A12: SupermarketSmall1990 | B12: 1990 | C12: 2010 | D12: =(B12+C12)/2 -> 2000 | E12: =dist_calculations!E$28 -> 15 | F12: =42/3 -> 14 | G12: 16 | H12: =E12*F12*G12/100 -> 33.6 | I12: =(G$36/C$36)*H12 -> 33.6
A13: Supermarket1980 | B13: 1985 | C13: 2010 | D13: =(B13+C13)/2 -> 1997.5 | E13: =dist_calculations!E$29 -> 10 | F13: 42 | G13: 16 | H13: =E13*F13*G13/100 -> 67.2 | I13: =(G$35/C$35)*H13 -> 67.661478
B15: Timeline
B16: Year | C16: Current eff. Consumption | D16: Source consumption | E16: Source (interpolated) | F16: Source (relative) | G16: Adj. Consumption | H16: First ripple
B17: 1750 | C17: =H2 -> 48 | H17: =I2 -> 72
B18: 1800 | C18: =H2 -> 48 | D18: =sources_consumption!D2 -> 28000 | F18: =(D18/D$36)*F$36 -> 68.362535 | G18: =(F18/F$36)*C$36 -> 68.909435 | H18: =I2 -> 72
B19: 1820 | C19: =H2+H3 -> 72 | E19: =_xlfn.FORECAST.LINEAR(B19,D$17:D$22,B$17:B$22) -> 31800 | F19: =(E19/D$36)*F$36 -> 77.640308 | G19: =(F19/F$36)*C$36 -> 78.26143 | H19: =I2+I3 -> 87
B20: 1830 | C20: =H2+H3 -> 72 | E20: =_xlfn.FORECAST.LINEAR(B20,D$17:D$22,B$17:B$22) -> 33700 | F20: =(E20/D$36)*F$36 -> 82.279194 | G20: =(F20/F$36)*C$36 -> 82.937427 | H20: =I2+I3 -> 87
B21: 1840 | C21: =H4+H5 -> 117.6 | E21: =_xlfn.FORECAST.LINEAR(B21,D$17:D$22,B$17:B$22) -> 35600 | F21: =(E21/D$36)*F$36 -> 86.91808 | G21: =(F21/F$36)*C$36 -> 87.613425 | H21: =I4+I5 -> 110
B22: 1880 | C22: =H4+H5 -> 117.6 | D22: =sources_consumption!D9 -> 43200 | F22: =(D22/D$36)*F$36 -> 105.47363 | G22: =(F22/F$36)*C$36 -> 106.31741 | H22: =I4+I5 -> 110
B23: 1900 | C23: =H4+H5 -> 117.6 | E23: =_xlfn.FORECAST.LINEAR(B23,D$22:D$24,B$22:B$24) -> 45866.667 | F23: =(E23/D$36)*F$36 -> 111.98434 | G23: =(F23/F$36)*C$36 -> 112.88022 | H23: =I4+I5 -> 110
B24: 1910 | C24: =H6+H7 -> 93.8 | D24: =sources_consumption!D12 -> 47200 | F24: =(D24/D$36)*F$36 -> 115.2397 | G24: =(F24/F$36)*C$36 -> 116.16162 | H24: =I6+I7 -> 123.65447
B25: 1928 | C25: =H6+H7 -> 93.8 | E25: =_xlfn.FORECAST.LINEAR(B25,D$24:D$26,B$24:B$26) -> 50244.571 | F25: =(E25/D$36)*F$36 -> 122.67308 | G25: =(F25/F$36)*C$36 -> 123.65447 | H25: =I6+I7 -> 123.65447
B26: 1935 | C26: =H6+H7 -> 93.8 | D26: =sources_consumption!D18 -> 51428.571 | F26: =(D26/D$36)*F$36 -> 125.56384 | G26: =(F26/F$36)*C$36 -> 126.56835 | H26: =I6+I7 -> 123.65447
B27: 1945 | C27: =H8+H9 -> 55.68 | E27: =_xlfn.FORECAST.LINEAR(B27,D$26:D$31,B$26:B$31) -> 49642.449 | F27: =(E27/D$36)*F$36 -> 121.20299 | G27: =(F27/F$36)*C$36 -> 122.17261 | H27: =I8+I9 -> 97.862514
B28: 1950 | C28: =H8+H9 -> 55.68 | E28: =_xlfn.FORECAST.LINEAR(B28,D$26:D$31,B$26:B$31) -> 48749.388 | F28: =(E28/D$36)*F$36 -> 119.02256 | G28: =(F28/F$36)*C$36 -> 119.97474 | H28: =I8+I9 -> 97.862514
A29: Butchery1945+Market1945 | B29: 1960 | C29: =H8+H9+H10 -> 65.76 | E29: =_xlfn.FORECAST.LINEAR(B29,D$26:D$31,B$26:B$31) -> 46963.265 | F29: =(E29/D$36)*F$36 -> 114.66171 | G29: =(F29/F$36)*C$36 -> 115.579 | H29: =I8+I9+I10 -> 105.29045
A30: Supermarket1950 | B30: 1966 | C30: =H8+H9+H10+H11 -> 150.88 | E30: =_xlfn.FORECAST.LINEAR(B30,D$26:D$31,B$26:B$31) -> 45891.592 | F30: =(E30/D$36)*F$36 -> 112.0452 | G30: =(F30/F$36)*C$36 -> 112.94156 | H30: =I8+I9+I10+I11 -> 203.15406
B31: 1970 | C31: =H8+H9+H10+H11 -> 150.88 | D31: =sources_consumption!D24 -> 45177.143 | F31: =(D31/D$36)*F$36 -> 110.30086 | G31: =(F31/F$36)*C$36 -> 111.18326 | H31: =I8+I9+I10+I11 -> 203.15406
A32: Supermarket1960 | B32: 1975 | C32: =H10+H11 -> 95.2 | E32: =_xlfn.FORECAST.LINEAR(B32,D$31:D$36,B$31:B$36) -> 44473.97 | F32: =(E32/D$36)*F$36 -> 108.58405 | G32: =(F32/F$36)*C$36 -> 109.45272 | H32: =I10+I11 -> 105.29155
B33: 1980 | C33: =H10+H11 -> 95.2 | E33: =_xlfn.FORECAST.LINEAR(B33,D$31:D$36,B$31:B$36) -> 43770.797 | F33: =(E33/D$36)*F$36 -> 106.86724 | G33: =(F33/F$36)*C$36 -> 107.72218 | H33: =I10+I11 -> 105.29155
B34: 1982 | C34: =H11 -> 85.12 | E34: =_xlfn.FORECAST.LINEAR(B34,D$31:D$36,B$31:B$36) -> 43489.528 | F34: =(E34/D$36)*F$36 -> 106.18051 | G34: =(F34/F$36)*C$36 -> 107.02996 | H34: =I11 -> 97.863609
A35: Supermarket1980 | B35: 1998 | C35: =H12+H13 -> 100.8 | E35: =_xlfn.FORECAST.LINEAR(B35,D$31:D$36,B$31:B$36) -> 41239.376 | F35: =(E35/D$36)*F$36 -> 100.68672 | G35: =(F35/F$36)*C$36 -> 101.49222 | H35: =I12+I13 -> 101.26148
A36: SupermarketSmall1990 | B36: 2000 | C36: =H12+H13 -> 100.8 | D36: =sources_consumption!D31 -> 40958.107 | F36: 100 | G36: =(F36/F$36)*C$36 -> 100.8 | H36: =I11+I13 -> 165.52509

Sheet milk
A1: Industry | B1: Start year | C1: End year | D1: Midpoint | E1: distributionweight | F1: productivity | G1: InputFactor | H1: eff. Consumption | I1: Modified Consumption
A2: Dairy1750 | B2: 1750 | C2: 1840 | D2: =(B2+C2)/2 -> 1795 | E2: 42 | F2: 5 | G2: 100 | H2: =E2*F2*G2/100 -> 210 | I2: =(G13/C13)*H2 -> 48.818826
A3: Dairy1840 | B3: 1841 | C3: 1910 | D3: =(B3+C3)/2 -> 1875.5 | E3: 21 | F3: 10 | G3: 100 | H3: =E3*F3*G3/100 -> 210 | I3: =(G16/C16)*H3 -> 88.687537
A4: Dairy1910 | B4: 1911 | C4: 1945 | D4: =(B4+C4)/2 -> 1928 | E4: 15 | F4: 15 | G4: 100 | H4: =E4*F4*G4/100 -> 225 | I4: =(G19/C19)*H4 -> 156.03428
A5: Supermarket1950 | B5: 1950 | C5: 1975 | D5: =(B5+C5)/2 -> 1962.5 | E5: =dist_calculations!E22 -> 8 | F5: 7 | G5: 14 | H5: =E5*F5*G5/100 -> 7.84 | I5: =(G23/C23)*H5 -> 20.692731
A6: Supermarket1960 | B6: 1960 | C6: 1990 | D6: =(B6+C6)/2 -> 1975 | E6: =dist_calculations!E$24 -> 38 | F6: 14 | G6: 14 | H6: =E6*F6*G6/100 -> 74.48 | I6: =(G25/C25)*H6 -> 217.80309
A7: Convenience1975 | B7: 1975 | C7: 2010 | D7: =(B7+C7)/2 -> 1992.5 | E7: 2 | F7: 8 | G7: 18 | H7: =E7*F7*G7/100 -> 2.88 | I7: =(G27/C27)*H7 -> 3.0898641
A8: SupermarketSmall1990 | B8: 1990 | C8: 2010 | D8: =(B8+C8)/2 -> 2000 | E8: =dist_calculations!E28 -> 15 | F8: =42/3 -> 14 | G8: 28 | H8: =E8*F8*G8/100 -> 58.8 | I8: =(G29/C29)*H8 -> 58.8
A9: Supermarket1980 | B9: 1985 | C9: 2010 | D9: =(B9+C9)/2 -> 1997.5 | E9: =dist_calculations!E29 -> 10 | F9: 42 | G9: 28 | H9: =E9*F9*G9/100 -> 117.6 | I9: =(G28/C28)*H9 -> 120.25734
B10: Timeline
B11: Year | C11: Current eff. Cons. | D11: Source consumption | E11: Source (interpolated) | F11: Source (relative) | G11: Adj. Consumption | H11: New consumption
B12: 1750 | C12: =H2 -> 210 | H12: =I2 -> 48.818826
B13: 1800 | C13: =H2 -> 210 | D13: =sources_consumption!D6 -> 681.91376 | F13: =(D13/D$29)*F$29 -> 27.675071 | G13: =(F13/F$29)*C$29 -> 48.818826 | H13: =I2 -> 48.818826
B14: 1820 | C14: =H2 -> 210 | E14: =_xlfn.FORECAST.LINEAR(B14,D$13:D$15,B$13:B$15) -> 609.17629 | F14: =(E14/D$29)*F$29 -> 24.723064 | G14: =(F14/F$29)*C$29 -> 43.611484 | H14: =I2 -> 48.818826
B15: 1850 | D15: =sources_consumption!D7 -> 500.07008 | F15: =(D15/D$29)*F$29 -> 20.295052 | G15: =(F15/F$29)*C$29 -> 35.800472 | H15: =I3 -> 88.687537
B16: 1875 | C16: =H3 -> 210 | E16: =_xlfn.FORECAST.LINEAR(B16,D$15:D$18,B$15:B$18) -> 1238.81 | F16: =(E16/D$29)*F$29 -> 50.276382 | G16: =(F16/F$29)*C$29 -> 88.687537 | H16: =I3 -> 88.687537
B17: 1900 | C17: =H3 -> 210 | E17: =_xlfn.FORECAST.LINEAR(B17,D$15:D$18,B$15:B$18) -> 1977.55 | F17: =(E17/D$29)*F$29 -> 80.257712 | G17: =(F17/F$29)*C$29 -> 141.5746 | H17: =I3 -> 88.687537
B18: 1910 | C18: =H4 -> 225 | D18: =sources_consumption!D17 -> 2273.046 | F18: =(D18/D$29)*F$29 -> 92.250244 | G18: =(F18/F$29)*C$29 -> 162.72943 | H18: =I4 -> 156.03428
B19: 1928 | C19: =H4 -> 225 | E19: =_xlfn.FORECAST.LINEAR(B19,D$18:D$20,B$18:B$20) -> 2179.5264 | F19: =(E19/D$29)*F$29 -> 88.454805 | G19: =(F19/F$29)*C$29 -> 156.03428 | H19: =I4 -> 156.03428
B20: 1935 | C20: =H4 -> 225 | D20: =sources_consumption!D23 -> 2143.1577 | F20: =(D20/D$29)*F$29 -> 86.978801 | G20: =(F20/F$29)*C$29 -> 153.4306 | H20: =I4 -> 156.03428
B21: 1945 | C21: =H4 -> 225 | E21: =_xlfn.FORECAST.LINEAR(B21,D$20:D$24,B$20:B$24) -> 2473.4452 | F21: =(E21/D$29)*F$29 -> 100.38333 | G21: =(F21/F$29)*C$29 -> 177.07619 | H21: =I4 -> 156.03428
B22: 1960 | C22: =H6+H5 -> 82.32 | E22: =_xlfn.FORECAST.LINEAR(B22,D$20:D$24,B$20:B$24) -> 2968.8764 | F22: =(E22/D$29)*F$29 -> 120.49011 | G22: =(F22/F$29)*C$29 -> 212.54456 | H22: =I5+I6 -> 238.49582
B23: 1962 | C23: =H6+H5 -> 82.32 | E23: =_xlfn.FORECAST.LINEAR(B23,D$20:D$24,B$20:B$24) -> 3034.9339 | F23: =(E23/D$29)*F$29 -> 123.17102 | G23: =(F23/F$29)*C$29 -> 217.27368 | H23: =I5+I6 -> 238.49582
B24: 1970 | C24: =H6 -> 74.48 | D24: =sources_consumption!D29 -> 3299.1639 | F24: =(D24/D$29)*F$29 -> 133.89464 | G24: =(F24/F$29)*C$29 -> 236.19014 | H24: =I5+I6 -> 238.49582
B25: 1975 | C25: =H6+H7 -> 77.36 | E25: =_xlfn.FORECAST.LINEAR(B25,D$24:D$29,B$24:B$29) -> 3159.9699 | F25: =(E25/D$29)*F$29 -> 128.24553 | G25: =(F25/F$29)*C$29 -> 226.22512 | H25: =I6 -> 217.80309
B26: 1985 | C26: =H6+H9 -> 192.08 | E26: =_xlfn.FORECAST.LINEAR(B26,D$24:D$29,B$24:B$29) -> 2881.582 | F26: =(E26/D$29)*F$29 -> 116.94732 | G26: =(F26/F$29)*C$29 -> 206.29507 | H26: =I6+I9 -> 338.06043
B27: 1992 | C27: =H7+H8+H9 -> 179.28 | E27: =_xlfn.FORECAST.LINEAR(B27,D$24:D$29,B$24:B$29) -> 2686.7104 | F27: =(E27/D$29)*F$29 -> 109.03857 | G27: =(F27/F$29)*C$29 -> 192.34404 | H27: =I7+I8+I9 -> 182.1472
B28: 1998 | C28: =H8+H9 -> 176.4 | E28: =_xlfn.FORECAST.LINEAR(B28,D$24:D$29,B$24:B$29) -> 2519.6776 | F28: =(E28/D$29)*F$29 -> 102.25964 | G28: =(F28/F$29)*C$29 -> 180.38601 | H28: =I8+I9 -> 179.05734
B29: 2000 | C29: =H8+H9 -> 176.4 | D29: =sources_consumption!D36 -> 2464 | F29: 100 | G29: =(F29/F$29)*C$29 -> 176.4 | H29: =I8+I9 -> 179.05734

Sheet fish
A1: Industry | B1: Start year | C1: End year | D1: Midpoint | E1: distributionweight | F1: productivity | G1: InputFactor | H1: eff. Consumption | I1: Modified Consumption
A2: Market1750 | B2: 1750 | C2: 1840 | D2: =(B2+C2)/2 -> 1795 | E2: 75 | F2: 4 | G2: 5 | H2: =E2*F2*G2/100 -> 15 | I2: =(G18/C18)*H2 -> 197.66064
A3: Fishmongers1820 | B3: 1818 | C3: 1840 | D3: =(B3+C3)/2 -> 1829 | E3: 27 | F3: 2 | G3: 100 | H3: =E3*F3*G3/100 -> 54 | I3: =((G20)/H3)*H3 -> 242.47904
A4: Market1840 | B4: 1841 | C4: 1910 | D4: =(B4+C4)/2 -> 1875.5 | E4: 45 | F4: 8 | G4: 5 | H4: =E4*F4*G4/100 -> 18 | I4: =(G23/C23)*H4 -> 36.436076
A5: Fishmongers1840 | B5: 1841 | C5: 1910 | D5: =(B5+C5)/2 -> 1875.5 | E5: 27 | F5: 5 | G5: 100 | H5: =E5*F5*G5/100 -> 135 | I5: =(G23/C23)*H5 -> 273.27057
A6: Market1910 | B6: 1911 | C6: 1945 | D6: =(B6+C6)/2 -> 1928 | E6: 10 | F6: 8 | G6: 5 | H6: =E6*F6*G6/100 -> 4 | I6: =(G27/C27)*H6 -> 7.2688938
A7: Fishmongers1910 | B7: 1911 | C7: 1945 | D7: =(B7+C7)/2 -> 1928 | E7: 21 | F7: 10 | G7: 100 | H7: =E7*F7*G7/100 -> 210 | I7: =(G27/C27)*H7 -> 381.61692
A8: Market1945 | B8: 1946 | C8: 1975 | D8: =(B8+C8)/2 -> 1960.5 | E8: 4 | F8: 12 | G8: 5 | H8: =E8*F8*G8/100 -> 2.4 | I8: =(G31/C31)*H8 -> 2.881003
A9: Fishmongers1945 | B9: 1946 | C9: 2010 | D9: =(B9+C9)/2 -> 1978 | E9: 12 | F9: 15 | G9: 100 | H9: =E9*F9*G9/100 -> 180 | I9: =(G35/C35)*H9 -> 172.24999
A10: Supermarket1950 | B10: 1950 | C10: 1982 | D10: =(B10+C10)/2 -> 1966 | E10: 9 | F10: 7 | G10: 5 | H10: =E10*F10*G10/100 -> 3.15 | I10: =(G32/C32)*H10 -> 3.2657655
A11: Supermarket1960 | B11: 1960 | C11: 1990 | D11: =(B11+C11)/2 -> 1975 | E11: =dist_calculations!E$24 -> 38 | F11: 14 | G11: 5 | H11: =E11*F11*G11/100 -> 26.6 | I11: =(G34/C34)*H11 -> 25.268282
A12: SupermarketSmall1990 | B12: 1990 | C12: 2010 | D12: =(B12+C12)/2 -> 2000 | E12: =dist_calculations!E$28 -> 15 | F12: =42/3 -> 14 | G12: 5 | H12: =E12*F12*G12/100 -> 10.5 | I12: =(G39/C39)*H12 -> 10.5
A13: Supermarket1980 | B13: 1985 | C13: 2010 | D13: =(B13+C13)/2 -> 1997.5 | E13: =dist_calculations!E$29 -> 10 | F13: 42 | G13: 5 | H13: =E13*F13*G13/100 -> 21 | I13: =(G38/C38)*H13 -> 20.902687
B15: Timeline
B16: Year | C16: Current eff. Consumption | D16: Source consumption | E16: Source (interpolated) | F16: Source (relative) | G16: Adj. Consumption | H16: New consumption
B17: 1750 | C17: =H2 -> 15 | E17: =_xlfn.FORECAST.LINEAR(B17,D$25:D$28,B$25:B$28) -> 3820.3128 | F17: =(E17/D$39)*100 -> 58.138679 | G17: =(F17/F$39)*C$39 -> 122.96331
B18: 1800 | C18: =H2 -> 15 | E18: =_xlfn.FORECAST.LINEAR(B18,D$25:D$28,B$25:B$28) -> 6141.0636 | F18: =(E18/D$39)*100 -> 93.456568 | G18: =(F18/F$39)*C$39 -> 197.66064 | H18: =I2 -> 197.66064
B19: 1818 | C19: =H2+H3 -> 69 | E19: =_xlfn.FORECAST.LINEAR(B19,D$25:D$28,B$25:B$28) -> 6976.5339 | F19: =(E19/D$39)*100 -> 106.17101 | G19: =(F19/F$39)*C$39 -> 224.55168
B20: 1830 | C20: =H2+H3 -> 69 | E20: =_xlfn.FORECAST.LINEAR(B20,D$25:D$28,B$25:B$28) -> 7533.5141 | F20: =(E20/D$39)*100 -> 114.6473 | G20: =(F20/F$39)*C$39 -> 242.47904 | H20: =I2+I3 -> 440.13968
B21: 1840 | C21: =H2+H3 -> 69 | E21: =_xlfn.FORECAST.LINEAR(B21,D$25:D$28,B$25:B$28) -> 7997.6642 | F21: =(E21/D$39)*100 -> 121.71088 | G21: =(F21/F$39)*C$39 -> 257.41851
B22: 1841 | C22: =H4+H5 -> 153 | E22: =_xlfn.FORECAST.LINEAR(B22,D$25:D$28,B$25:B$28) -> 8044.0792 | F22: =(E22/D$39)*100 -> 122.41724 | G22: =(F22/F$39)*C$39 -> 258.91246
B23: 1875 | C23: =H4+H5 -> 153 | E23: =_xlfn.FORECAST.LINEAR(B23,D$25:D$28,B$25:B$28) -> 9622.1898 | F23: =(E23/D$39)*100 -> 146.4334 | G23: =(F23/F$39)*C$39 -> 309.70664 | H23: =I4+I5 -> 309.70664
B24: 1900 | C24: =H4+H5 -> 153 | E24: =_xlfn.FORECAST.LINEAR(B24,D$25:D$28,B$25:B$28) -> 10782.565 | F24: =(E24/D$39)*100 -> 164.09235 | G24: =(F24/F$39)*C$39 -> 347.05531
B25: 1910 | C25: =H4+H5 -> 153 | D25: =sources_consumption!D13 -> 11246.715 | F25: =(D25/D$39)*100 -> 171.15592 | G25: =(F25/F$39)*C$39 -> 361.99478
B26: 1911 | C26: =H6+H7 -> 214 | E26: =_xlfn.FORECAST.LINEAR(B26,D$25:D$28,B$25:B$28) -> 11293.13 | F26: =(E26/D$39)*100 -> 171.86228 | G26: =(F26/F$39)*C$39 -> 363.48872
B27: 1928 | C27: =H6+H7 -> 214 | E27: =_xlfn.FORECAST.LINEAR(B27,D$25:D$28,B$25:B$28) -> 12082.186 | F27: =(E27/D$39)*100 -> 183.87036 | G27: =(F27/F$39)*C$39 -> 388.88582 | H27: =I6+I7 -> 388.88582
B28: 1935 | C28: =H6+H7 -> 214 | D28: =sources_consumption!D19 -> 12407.091 | F28: =(D28/D$39)*100 -> 188.81487 | G28: =(F28/F$39)*C$39 -> 399.34344
B29: 1946 | C29: =H8+H9 -> 182.4 | E29: =_xlfn.FORECAST.LINEAR(B29,D$28:D$33,B$28:B$33) -> 10429.352 | F29: =(E29/D$39)*100 -> 158.71704 | G29: =(F29/F$39)*C$39 -> 335.68654
B30: 1950 | C30: =H8+H9+H10 -> 185.55 | E30: =_xlfn.FORECAST.LINEAR(B30,D$28:D$33,B$28:B$33) -> 9710.1743 | F30: =(E30/D$39)*100 -> 147.77238 | G30: =(F30/F$39)*C$39 -> 312.53857
B31: 1960 | C31: =H8+H9+H10+H11 -> 212.15 | E31: =_xlfn.FORECAST.LINEAR(B31,D$28:D$33,B$28:B$33) -> 7912.23 | F31: =(E31/D$39)*100 -> 120.41071 | G31: =(F31/F$39)*C$39 -> 254.66866 | H31: =I8+I9+I10 -> 178.39676
B32: 1966 | C32: =H8+H9+H10+H11 -> 212.15 | E32: =_xlfn.FORECAST.LINEAR(B32,D$28:D$33,B$28:B$33) -> 6833.4634 | F32: =(E32/D$39)*100 -> 103.99372 | G32: =(F32/F$39)*C$39 -> 219.94671 | H32: =I8+I9+I10+I11 -> 203.66504
B33: 1970 | C33: =H8+H9+H10+H11 -> 212.15 | D33: =sources_consumption!D25 -> 6114.2857 | F33: =(D33/D$39)*100 -> 93.049053 | G33: =(F33/F$39)*C$39 -> 196.79875
B34: 1975 | C34: =H9+H10+H11 -> 209.75 | E34: =_xlfn.FORECAST.LINEAR(B34,D$33:D$39,B$33:B$39) -> 6190.4106 | F34: =(E34/D$39)*100 -> 94.207545 | G34: =(F34/F$39)*C$39 -> 199.24896 | H34: =I9+I10+I11 -> 200.78403
B35: 1978 | C35: =H9+H10+H11 -> 209.75 | E35: =_xlfn.FORECAST.LINEAR(B35,D$33:D$39,B$33:B$39) -> 6236.0855 | F35: =(E35/D$39)*100 -> 94.902639 | G35: =(F35/F$39)*C$39 -> 200.71908 | H35: =I9+I10+I11 -> 200.78403
B36: 1982 | C36: =H9+H11 -> 206.6 | E36: =_xlfn.FORECAST.LINEAR(B36,D$33:D$39,B$33:B$39) -> 6296.9854 | F36: =(E36/D$39)*100 -> 95.829432 | G36: =(F36/F$39)*C$39 -> 202.67925
B37: 1985 | C37: =H9+H11+H13 -> 227.6 | E37: =_xlfn.FORECAST.LINEAR(B37,D$33:D$39,B$33:B$39) -> 6342.6603 | F37: =(E37/D$39)*100 -> 96.524527 | G37: =(F37/F$39)*C$39 -> 204.14937
B38: 1998 | C38: =H9+H12+H13 -> 211.5 | E38: =_xlfn.FORECAST.LINEAR(B38,D$33:D$39,B$33:B$39) -> 6540.5849 | F38: =(E38/D$39)*100 -> 99.536604 | G38: =(F38/F$39)*C$39 -> 210.51992 | H38: =I9+I12+I13 -> 203.65267
B39: 2000 | C39: =H9+H12+H13 -> 211.5 | D39: =sources_consumption!D32 -> 6571.0348 | F39: 100 | G39: =(F39/F$39)*C39 -> 211.5 | H39: =I9+I12+I13 -> 203.65267

Sheet flour
A1: Industry | B1: Start year | C1: End year | D1: Midpoint | E1: distributionweight | F1: productivity | G1: InputFactor | H1: eff. Consumption | I1: Modified Consumption
A2: Bakery1750 | B2: 1750 | C2: 1840 | D2: =(B2+C2)/2 -> 1795 | E2: 32 | F2: 1 | G2: 100 | H2: =E2*F2*G2/100 -> 32 | I2: =(G$17/C$17)*H2 -> 107.28094
A3: Bakery1840 | B3: 1841 | C3: 1910 | D3: =(B3+C3)/2 -> 1875.5 | E3: 30 | F3: 2 | G3: 100 | H3: =E3*F3*G3/100 -> 60 | I3: =(G$20/C$20)*H3 -> 90.51829
A4: Bakery1910 | B4: 1911 | C4: 1945 | D4: =(B4+C4)/2 -> 1928 | E4: 27 | F4: 3 | G4: 100 | H4: =E4*F4*G4/100 -> 81 | I4: =(G$24/C$24)*H4 -> 53.040206
A5: Bakery1945 | B5: 1946 | C5: 1975 | D5: =(B5+C5)/2 -> 1960.5 | E5: 24 | F5: 4 | G5: 100 | H5: =E5*F5*G5/100 -> 96 | I5: =(G$26/C$26)*H5 -> 48.22914
A6: Supermarket1950 | B6: 1951 | C6: 1982 | D6: =(B6+C6)/2 -> 1966.5 | E6: 9 | F6: 7 | G6: 8 | H6: =E6*F6*G6/100 -> 5.04 | I6: =(G$27/C$27)*H6 -> 1.7748181
A7: Supermarket1960 | B7: 1960 | C7: 1990 | D7: 1975 | E7: =dist_calculations!E$24 -> 38 | F7: 14 | G7: 8 | H7: =E7*F7*G7/100 -> 42.56 | I7: =(G$29/C$29)*H7 -> 45.093036
A8: SupermarketSmall1990 | B8: 1990 | C8: 2010 | D8: =(B8+C8)/2 -> 2000 | E8: =dist_calculations!E$28 -> 15 | F8: =42/3 -> 14 | G8: 8 | H8: =E8*F8*G8/100 -> 16.8 | I8: =(G$31/C$31)*H8 -> 16.8
A9: Supermarket1980 | B9: 1985 | C9: 2010 | D9: =(B9+C9)/2 -> 1997.5 | E9: =dist_calculations!E$29 -> 10 | F9: 42 | G9: 8 | H9: =E9*F9*G9/100 -> 33.6 | I9: =(G$30/C$30)*H9 -> 33.60176
B14: Timeline
B15: Year | C15: Current eff. Consumption | D15: Source consumption | E15: Source (interpolated) | F15: Source (relative) | G15: Adj. Consumption | H15: New consumption
B16: 1750 | C16: =H2 -> 32
B17: 1800 | C17: =H2 -> 32 | D17: =sources_consumption!D3 -> 153600 | E17: =_xlfn.FORECAST.LINEAR(B17,D$17:D$22,B$17:B$22) -> 153600 | F17: =(E17/D$31)*F$31 -> 212.859 | G17: =(F17/F$31)*C$31 -> 107.28094 | H17: =I2 -> 107.28094
B18: 1820 | C18: =H2 -> 32 | E18: =_xlfn.FORECAST.LINEAR(B18,D$17:D$22,B$17:B$22) -> 147200 | F18: =(E18/D$31)*F$31 -> 203.98988 | G18: =(F18/F$31)*C$31 -> 102.8109 | H18: =I2 -> 107.28094
B19: 1841 | C19: =H3 -> 60 | E19: =_xlfn.FORECAST.LINEAR(B19,D$17:D$22,B$17:B$22) -> 140480 | F19: =(E19/D$31)*F$31 -> 194.67729 | G19: =(F19/F$31)*C$31 -> 98.117357 | H19: =I3 -> 90.51829
B20: 1875 | C20: =H3 -> 60 | E20: =_xlfn.FORECAST.LINEAR(B20,D$17:D$22,B$17:B$22) -> 129600 | F20: =(E20/D$31)*F$31 -> 179.59978 | G20: =(F20/F$31)*C$31 -> 90.51829 | H20: =I3 -> 90.51829
B21: 1880 | C21: =H3 -> 60 | D21: =sources_consumption!D10 -> 128000 | E21: =_xlfn.FORECAST.LINEAR(B21,D$17:D$22,B$17:B$22) -> 128000 | F21: =(E21/D$31)*F$31 -> 177.3825 | G21: =(F21/F$31)*C$31 -> 89.40078 | H21: =I3 -> 90.51829
B22: 1900 | C22: =H3 -> 60 | E22: =_xlfn.FORECAST.LINEAR(B22,D$21:D$23,B$21:B$23) -> 96914.286 | F22: =(E22/D$31)*F$31 -> 134.30389 | G22: =(F22/F$31)*C$31 -> 67.689162 | H22: =I3 -> 90.51829
B23: 1910 | C23: =H4 -> 81 | D23: =sources_consumption!D14 -> 81371.429 | F23: =(D23/D$31)*F$31 -> 112.76459 | G23: =(F23/F$31)*C$31 -> 56.833353 | H23: =I4 -> 53.040206
B24: 1928 | C24: =H4 -> 81 | E24: =_xlfn.FORECAST.LINEAR(B24,D$23:D$25,B$23:B$25) -> 75940.571 | F24: =(E24/D$31)*F$31 -> 105.2385 | G24: =(F24/F$31)*C$31 -> 53.040206 | H24: =I4 -> 53.040206
B25: 1935 | C25: =H4 -> 81 | D25: =sources_consumption!D20 -> 73828.571 | F25: =(D25/D$31)*F$31 -> 102.31169 | G25: =(F25/F$31)*C$31 -> 51.565093 | H25: =I4 -> 53.040206
B26: 1960 | C26: =H5+H6 -> 101.04 | E26: =_xlfn.FORECAST.LINEAR(B26,D$25:D$28,B$25:B$28) -> 72677.551 | F26: =(E26/D$31)*F$31 -> 100.71661 | G26: =(F26/F$31)*C$31 -> 50.76117 | H26: =I5+I6 -> 50.003958
B27: 1966 | C27: =H5+H6+H7 -> 143.6 | E27: =_xlfn.FORECAST.LINEAR(B27,D$25:D$28,B$25:B$28) -> 72401.306 | F27: =(E27/D$31)*F$31 -> 100.33379 | G27: =(F27/F$31)*C$31 -> 50.568229 | H27: =I5+I6+I7 -> 95.096994
B28: 1970 | C28: =H5+H6+H7 -> 143.6 | D28: =sources_consumption!D26 -> 72217.143 | F28: =(D28/D$31)*F$31 -> 100.07857 | G28: =(F28/F$31)*C$31 -> 50.439601 | H28: =I5+I6+I7 -> 95.096994
B29: 1975 | C29: =H6+H7 -> 47.6 | E29: =_xlfn.FORECAST.LINEAR(B29,D$28:D$34,B$28:B$34) -> 72207.693 | F29: =(E29/D$31)*F$31 -> 100.06548 | G29: =(F29/F$31)*C$31 -> 50.433001 | H29: =I6+I7 -> 46.867854
B30: 1998 | C30: =H8+H9 -> 50.4 | E30: =_xlfn.FORECAST.LINEAR(B30,D$28:D$34,B$28:B$34) -> 72164.224 | F30: =(E30/D$31)*F$31 -> 100.00524 | G30: =(F30/F$31)*C$31 -> 50.40264 | H30: =I8+I9 -> 50.40176
B31: 2000 | C31: =H8+H9 -> 50.4 | D31: =sources_consumption!D33 -> 72160.444 | F31: 100 | G31: =(F31/F$31)*C$31 -> 50.4 | H31: =I8+I9 -> 50.40176

Sheet vegetables
A1: Industry | B1: Start year | C1: End year | D1: Midpoint | E1: distributionweight | F1: productivity | G1: InputFactor | H1: eff. Consumption | I1: Modified Consumption
A2: Market1750 | B2: 1750 | C2: 1840 | D2: =(B2+C2)/2 -> 1795 | E2: 75 | F2: 4 | G2: 31 | H2: =E2*F2*G2/100 -> 93 | I2: =(G$18/C$18)*H2 -> 40.147228
A3: Greengrocers1820 | B3: 1820 | C3: 1840 | D3: =(B3+C3)/2 -> 1830 | E3: 27 | F3: 1 | G3: 100 | H3: =E3*F3*G3/100 -> 27 | I3: =(G$19/C$19)*H3 -> 23.700316
A4: Market1840 | B4: 1841 | C4: 1910 | D4: =(B4+C4)/2 -> 1875.5 | E4: 45 | F4: 8 | G4: 31 | H4: =E4*F4*G4/100 -> 111.6 | I4: =(G$21/C$21)*H4 -> 126.92716
A5: Greenfrocers1840 | B5: 1841 | C5: 1911 | D5: =(B5+C5)/2 -> 1876 | E5: 36 | F5: 2 | G5: 75 | H5: =E5*F5*G5/100 -> 54 | I5: =(G$21/C$21)*H5 -> 61.41637
A6: Market1910 | B6: 1911 | C6: 1945 | D6: =(B6+C6)/2 -> 1928 | E6: 10 | F6: 8 | G6: 31 | H6: =E6*F6*G6/100 -> 24.8 | I6: =(G$24/C$24)*H6 -> 62.016283
A7: Greengrocers1910 | B7: 1911 | C7: 1945 | D7: =(B7+C7)/2 -> 1928 | E7: 30 | F7: 4 | G7: 67 | H7: =E7*F7*G7/100 -> 80.4 | I7: =(G$24/C$24)*H7 -> 201.05279
A8: Market1945 | B8: 1946 | C8: 1975 | D8: =(B8+C8)/2 -> 1960.5 | E8: 4 | F8: 12 | G8: 31 | H8: =E8*F8*G8/100 -> 14.88 | I8: =(G$26/C$26)*H8 -> 37.439898
A9: Greengrocers1945 | B9: 1946 | C9: 1987 | D9: =(B9+C9)/2 -> 1966.5 | E9: 15 | F9: 6 | G9: 67 | H9: =E9*F9*G9/100 -> 60.3 | I9: =(G$27/C$27)*H9 -> 53.703468
A10: Supermarket1950 | B10: 1951 | C10: 1982 | D10: =(B10+C10)/2 -> 1966.5 | E10: 9 | F10: 7 | G10: 31 | H10: =E10*F10*G10/100 -> 19.53 | I10: =(G$27/C$27)*H10 -> 17.393511
A11: Supermarket1960 | B11: 1960 | C11: 1990 | D11: =(B11+C11)/2 -> 1975 | E11: =dist_calculations!E$24 -> 38 | F11: 14 | G11: 31 | H11: =E11*F11*G11/100 -> 164.92 | I11: =(G$29/C$29)*H11 -> 197.87686
A12: SupermarketSmall1990 | B12: 1990 | C12: 2010 | D12: =(B12+C12)/2 -> 2000 | E12: =dist_calculations!E$28 -> 15 | F12: =42/3 -> 14 | G12: 31 | H12: =E12*F12*G12/100 -> 65.1 | I12: =(G$33/C$33)*H12 -> 65.1
A13: Supermarket1980 | B13: 1985 | C13: 2010 | D13: =(B13+C13)/2 -> 1997.5 | E13: =dist_calculations!E$29 -> 10 | F13: 42 | G13: 31 | H13: =E13*F13*G13/100 -> 130.2 | I13: =(G$32/C$32)*H13 -> 131.58718
B15: Timeline
A16: Midpoint industry | B16: Year | C16: Current eff. Consumption | D16: Source consumption | E16: Source (interpolated) | F16: Source (relative) | G16: Adj. Consumption | H16: New consumption
B17: 1750 | C17: =H2 -> 93
A18: Market1750 | B18: 1800 | C18: =H2 -> 93 | D18: =sources_consumption!D5 -> 21164 | F18: =(D18/E$22)*100 -> 20.556696 | G18: =(F18/F$33)*C$33 -> 40.147228 | H18: =I2 -> 40.147228
A19: Greengrocers1820 | B19: 1830 | C19: =H2+H3 -> 120 | E19: =_xlfn.FORECAST.LINEAR(B19,D$18:D$20,B$18:B$20) -> 46529.6 | F19: =(E19/D$33)*100 -> 53.934838 | G19: =(F19/F$33)*C$33 -> 105.33474 | H19: =I2+I3 -> 63.847544
B20: 1850 | C20: =H4+H5 -> 165.6 | D20: =sources_consumption!D8 -> 63440 | F20: =(D20/D$33)*100 -> 73.536547 | G20: =(F20/F$33)*C$33 -> 143.61688 | H20: =I4+I5 -> 188.34353
A21: Market1840+Greengrocers1840 | B21: 1875 | C21: =H4+H5 -> 165.6 | E21: =_xlfn.FORECAST.LINEAR(B21,D$20:D$23,B$20:B$23) -> 83197.143 | F21: =(E21/D$33)*100 -> 96.438062 | G21: =(F21/F$33)*C$33 -> 188.34353 | H21: =I4+I5 -> 188.34353
B22: 1900 | C22: =H4+H5 -> 165.6 | E22: =_xlfn.FORECAST.LINEAR(B22,D$20:D$23,B$20:B$23) -> 102954.29 | F22: =(E22/D$33)*100 -> 119.33958 | G22: =(F22/F$33)*C$33 -> 233.07019 | H22: =I4+I5 -> 188.34353
B23: 1910 | C23: =H4+H5 -> 165.6 | D23: =sources_consumption!D15 -> 110857.14 | F23: =(D23/D$33)*100 -> 128.50018 | G23: =(F23/F$33)*C$33 -> 250.96086 | H23: =I4+I5 -> 188.34353
A24: Market1910+Greengrocers1910 | B24: 1928 | C24: =H6+H7 -> 105.2 | E24: =_xlfn.FORECAST.LINEAR(B24,D$23:D$25,B$23:B$25) -> 116205.71 | F24: =(E24/D$33)*100 -> 134.69998 | G24: =(F24/F$33)*C$33 -> 263.06907 | H24: =I6+I7 -> 263.06907
B25: 1935 | C25: =H6+H7 -> 105.2 | D25: =sources_consumption!D21 -> 118285.71 | F25: =(D25/D$33)*100 -> 137.11102 | G25: =(F25/F$33)*C$33 -> 267.77782 | H25: =I6+I7 -> 263.06907
A26: Market1945 | B26: 1960 | C26: =H8+H9+H10 -> 94.71 | E26: =_xlfn.FORECAST.LINEAR(B26,D$25:D$28,B$25:B$28) -> 105265.31 | F26: =(E26/D$33)*100 -> 122.0184 | G26: =(F26/F$33)*C$33 -> 238.30193 | H26: =I8+I9+I10 -> 108.53688
A27: Greengrocers1945+Supermarket1950 | B27: 1966 | C27: =H8+H9+H10+H11 -> 259.63 | E27: =_xlfn.FORECAST.LINEAR(B27,D$25:D$28,B$25:B$28) -> 102140.41 | F27: =(E27/D$33)*100 -> 118.39617 | G27: =(F27/F$33)*C$33 -> 231.22772 | H27: =I8+I9+I10+I11 -> 306.41374
B28: 1970 | C28: =H8+H9+H10+H11 -> 259.63 | D28: =sources_consumption!D27 -> 100057.14 | F28: =(D28/D$33)*100 -> 115.98135 | G28: =(F28/F$33)*C$33 -> 226.51158 | H28: =I8+I9+I10+I11 -> 306.41374
A29: Supermarket1960 | B29: 1975 | C29: =H10+H11 -> 184.45 | E29: =_xlfn.FORECAST.LINEAR(B29,D$28:D$33,B$28:B$33) -> 97759.29 | F29: =(E29/D$33)*100 -> 113.31779 | G29: =(F29/F$33)*C$33 -> 221.30965 | H29: =I10+I11 -> 215.27037
B30: 1980 | C30: =H10+H11 -> 184.45 | E30: =_xlfn.FORECAST.LINEAR(B30,D$28:D$33,B$28:B$33) -> 95461.438 | F30: =(E30/D$33)*100 -> 110.65423 | G30: =(F30/F$33)*C$33 -> 216.10772 | H30: =I10+I11 -> 215.27037
B31: 1982 | C31: =H11 -> 164.92 | E31: =_xlfn.FORECAST.LINEAR(B31,D$28:D$33,B$28:B$33) -> 94542.297 | F31: =(E31/D$33)*100 -> 109.58881 | G31: =(F31/F$33)*C$33 -> 214.02695 | H31: =I11 -> 197.87686
A32: Supermarket1980 | B32: 1998 | C32: =H12+H13 -> 195.3 | E32: =_xlfn.FORECAST.LINEAR(B32,D$28:D$33,B$28:B$33) -> 87189.169 | F32: =(E32/D$33)*100 -> 101.06542 | G32: =(F32/F$33)*C$33 -> 197.38077 | H32: =I12+I13 -> 196.68718
B33: 2000 | C33: =H12+H13 -> 195.3 | D33: =sources_consumption!D34 -> 86270.028 | F33: 100 | G33: =(F33/F$33)*C$33 -> 195.3 | H33: =I12+I13 -> 196.68718

Sheet fruit
A1: Industry | B1: Start year | C1: End year | D1: Midpoint | E1: distributionweight | F1: productivity | G1: InputFactor | H1: eff. Consumption | I1: Modified eff. Consumption
A2: Market1750 | B2: 1750 | C2: 1840 | D2: =(B2+C2)/2 -> 1795 | E2: 75 | F2: 4 | G2: 16 | H2: =E2*F2*G2/100 -> 48 | I2: =(G$18/C$18)*H2 -> 32.724162
A3: Greengrocers1820 | B3: 1820 | C3: 1840 | D3: =(B3+C3)/2 -> 1830 | E3: 27 | F3: 1 | G3: 100 | H3: =E3*F3*G3/100 -> 27 | I3: =(G19/C19)*H3 -> 20.605367
A4: Market1840 | B4: 1841 | C4: 1910 | D4: =(B4+C4)/2 -> 1875.5 | E4: 45 | F4: 8 | G4: 16 | H4: =E4*F4*G4/100 -> 57.6 | I4: =(G$20/C$20)*H4 -> 41.780705
A5: Greenfrocers1840 | B5: 1841 | C5: 1911 | D5: =(B5+C5)/2 -> 1876 | E5: 36 | F5: 2 | G5: 100 | H5: =E5*F5*G5/100 -> 72 | I5: =(G$20/C$20)*H5 -> 52.225881
A6: Market1910 | B6: 1911 | C6: 1945 | D6: =(B6+C6)/2 -> 1928 | E6: 10 | F6: 8 | G6: 16 | H6: =E6*F6*G6/100 -> 12.8 | I6: =(G$23/C$23)*H6 -> 12.479976
A7: Greengrocers1910 | B7: 1911 | C7: 1945 | D7: =(B7+C7)/2 -> 1928 | E7: 30 | F7: 4 | G7: 100 | H7: =E7*F7*G7/100 -> 120 | I7: =(G$23/C$23)*H7 -> 116.99977
A8: Market1945 | B8: 1946 | C8: 1975 | D8: =(B8+C8)/2 -> 1960.5 | E8: 4 | F8: 12 | G8: 16 | H8: =E8*F8*G8/100 -> 7.68 | I8: =(G$25/C$25)*H8 -> 7.1532111
A9: Greengrocers1945 | B9: 1946 | C9: 1987 | D9: =(B9+C9)/2 -> 1966.5 | E9: 15 | F9: 6 | G9: 100 | H9: =E9*F9*G9/100 -> 90 | I9: =(G$26/C$26)*H9 -> 43.060401
A10: Supermarket1950 | B10: 1951 | C10: 1982 | D10: =(B10+C10)/2 -> 1966.5 | E10: 9 | F10: 7 | G10: 16 | H10: =E10*F10*G10/100 -> 10.08 | I10: =(G$26/C$26)*H10 -> 4.8227649
A11: Supermarket1960 | B11: 1960 | C11: 1990 | D11: =(B11+C11)/2 -> 1975 | E11: =dist_calculations!E$24 -> 38 | F11: 14 | G11: 16 | H11: =E11*F11*G11/100 -> 85.12 | I11: =(G$28/C$28)*H11 -> 79.765013
A12: SupermarketSmall1990 | B12: 1990 | C12: 2010 | D12: =(B12+C12)/2 -> 2000 | E12: =dist_calculations!E$28 -> 15 | F12: =42/3 -> 14 | G12: 16 | H12: =E12*F12*G12/100 -> 33.6 | I12: =(G$32/C$32)*H12 -> 33.6
A13: Supermarket1980 | B13: 1985 | C13: 2010 | D13: =(B13+C13)/2 -> 1997.5 | E13: =dist_calculations!E$29 -> 10 | F13: 42 | G13: 16 | H13: =E13*F13*G13/100 -> 67.2 | I13: =(G$31/C$31)*H13 -> 66.581913
B15: Timeline
A16: Midpoint industry | B16: Year | C16: Current eff. Consumption | D16: Source consumption | E16: Source (interpolated) | F16: Source (relative) | G16: Adj. Consumption | H16: New consumption | I16: Deviation
B17: 1750 | C17: =H2 -> 48
A18: Market1750 | B18: 1800 | C18: =H2 -> 48 | D18: =sources_consumption!D4 -> 9959.5294 | F18: =(D18/D$32)*100 -> 32.464446 | G18: =(F18/F$32)*C$32 -> 32.724162 | H18: =I2 -> 32.724162 | I18: =(H18/G18 -1)*100 -> 0
A19: Greengrocers1820 | B19: 1830 | C19: =H2+H3 -> 75 | E19: =_xlfn.FORECAST.LINEAR(B19,D$18:D$21,B$18:B$21) -> 17420 | F19: =(E19/D$32)*100 -> 56.782869 | G19: =(F19/F$32)*C$32 -> 57.237132 | H19: =I2+I3 -> 53.329529 | I19: =(H19/G19 -1)*100 -> -6.8270413
A20: Market1840+Greengrocers1840 | B20: 1875 | C20: =H4+H5 -> 129.6 | E20: =_xlfn.FORECAST.LINEAR(B20,D$18:D$21,B$18:B$21) -> 28610.706 | F20: =(E20/D$32)*100 -> 93.260502 | G20: =(F20/F$32)*C$32 -> 94.006586 | H20: =I4+I5 -> 94.006586 | I20: =(H20/G20 -1)*100 -> 0
B21: 1880 | C21: =H4+H5 -> 129.6 | D21: =sources_consumption!D11 -> 29854.118 | F21: =(D21/D$32)*100 -> 97.313573 | G21: =(F21/F$32)*C$32 -> 98.092081 | H21: =I4+I5 -> 94.006586 | I21: =(H21/G21 -1)*100 -> -4.164959
B22: 1900 | C22: =H4+H5 -> 129.6 | E22: =_xlfn.FORECAST.LINEAR(B22,D$21:D$27,B$21:B$27) -> 32841.814 | F22: =(E22/D$32)*100 -> 107.05238 | G22: =(F22/F$32)*C$32 -> 107.9088 | H22: =I4+I5 -> 94.006586 | I22: =(H22/G22 -1)*100 -> -12.883296
A23: Market1910+Greengrocers1910 | B23: 1928 | C23: =H6+H7 -> 132.8 | E23: =_xlfn.FORECAST.LINEAR(B23,D$21:D$24,B$21:B$24) -> 39406.888 | F23: =(E23/D$32)*100 -> 128.45213 | G23: =(F23/F$32)*C$32 -> 129.47975 | H23: =I6+I7 -> 129.47975 | I23: =(H23/G23 -1)*100 -> 0
B24: 1935 | C24: =H6+H7 -> 132.8 | D24: =sources_consumption!D22 -> 40800 | F24: =(D24/D$32)*100 -> 132.99317 | G24: =(F24/F$32)*C$32 -> 134.05712 | H24: =I6+I7 -> 129.47975 | I24: =(H24/G24 -1)*100 -> -3.4144909
A25: Market1945 | B25: 1960 | C25: =H8+H9+H10 -> 107.76 | E25: =_xlfn.FORECAST.LINEAR(B25,D$24:D$27,B$24:B$27) -> 30546.939 | F25: =(E25/D$32)*100 -> 99.571918 | G25: =(F25/F$32)*C$32 -> 100.36849 | H25: =I8+I9+I10 -> 55.036377 | I25: =(H25/G25 -1)*100 -> -45.165684
A26: Greengrocers1945+Supermarket1950 | B26: 1966 | C26: =H8+H9+H10+H11 -> 192.88 | E26: =_xlfn.FORECAST.LINEAR(B26,D$24:D$27,B$24:B$27) -> 28086.204 | F26: =(E26/D$32)*100 -> 91.550817 | G26: =(F26/F$32)*C$32 -> 92.283224 | H26: =I8+I9+I10+I11 -> 134.80139 | I26: =(H26/G26 -1)*100 -> 46.07356
B27: 1970 | C27: =H8+H9+H10+H11 -> 192.88 | D27: =sources_consumption!D28 -> 26445.714 | F27: =(D27/D$32)*100 -> 86.203417 | G27: =(F27/F$32)*C$32 -> 86.893044 | H27: =I8+I9+I10+I11 -> 134.80139 | I27: =(H27/G27 -1)*100 -> 55.134846
A28: Supermarket1960 | B28: 1975 | C28: =H10+H11 -> 95.2 | E28: =_xlfn.FORECAST.LINEAR(B28,D$27:D$32,B$27:B$32) -> 27151.14 | F28: =(E28/D$32)*100 -> 88.502847 | G28: =(F28/F$32)*C$32 -> 89.21087 | H28: =I10+I11 -> 84.587778 | I28: =(H28/G28 -1)*100 -> -5.182207
B29: 1980 | C29: =H10+H11 -> 95.2 | E29: =_xlfn.FORECAST.LINEAR(B29,D$27:D$32,B$27:B$32) -> 27856.565 | F29: =(E29/D$32)*100 -> 90.802278 | G29: =(F29/F$32)*C$32 -> 91.528696 | H29: =I10+I11 -> 84.587778 | I29: =(H29/G29 -1)*100 -> -7.5833244
B30: 1982 | C30: =H11 -> 85.12 | E30: =_xlfn.FORECAST.LINEAR(B30,D$27:D$32,B$27:B$32) -> 28138.735 | F30: =(E30/D$32)*100 -> 91.72205 | G30: =(F30/F$32)*C$32 -> 92.455826 | H30: =I11 -> 79.765013 | I30: =(H30/G30 -1)*100 -> -13.726353
A31: Supermarket1980 | B31: 1998 | C31: =H12+H13 -> 100.8 | E31: =_xlfn.FORECAST.LINEAR(B31,D$27:D$32,B$27:B$32) -> 30396.097 | F31: =(E31/D$32)*100 -> 99.080228 | G31: =(F31/F$32)*C$32 -> 99.87287 | H31: =I12+I13 -> 100.18191 | I31: =(H31/G31 -1)*100 -> 0.30943685
A32: SupermarketSmall1990 | B32: 2000 | C32: =H12+H13 -> 100.8 | D32: =sources_consumption!D35 -> 30678.267 | F32: 100 | G32: =(F32/F$32)*C$32 -> 100.8 | H32: =I12+I13 -> 100.18191 | I32: =(H32/G32 -1)*100 -> -0.61318148

Sheet canned
A1: Industry | B1: Start year | C1: End year | D1: Midpoint | E1: distributionweight | F1: productivity | G1: InputFactor | H1: eff. Consumption | I1: Modified Consumption
A2: Grocer1810 | B2: 1810 | C2: 1860 | D2: =(B2+C2)/2 -> 1835 | E2: 8 | F2: 4 | G2: 33 | H2: =E2*F2*G2/100 -> 10.56 | I2: =(G$17/C$17)*H2 -> 13.241865
A3: Grocer1860 | B3: 1861 | C3: 1900 | D3: =(B3+C3)/2 -> 1880.5 | E3: 28 | F3: 4 | G3: 33 | H3: =E3*F3*G3/100 -> 36.96 | I3: =(G$18/C$18)*H3 -> 37.077222
A4: Grocer1900 | B4: 1900 | C4: 1945 | D4: =(B4+C4)/2 -> 1922.5 | E4: 45 | F4: 8 | G4: 33 | H4: =E4*F4*G4/100 -> 118.8 | I4: =(G$19/C$19)*H4 -> 59.85323
A5: Grocer1945 | B5: 1945 | C5: 1975 | D5: =(B5+C5)/2 -> 1960 | E5: 24 | F5: 8 | G5: 33 | H5: =E5*F5*G5/100 -> 63.36 | I5: =(G$21/C$21)*H5 -> 66.272082
A6: Supermarket1950 | B6: 1951 | C6: 1982 | D6: =(B6+C6)/2 -> 1966.5 | E6: 9 | F6: 7 | G6: 20 | H6: =E6*F6*G6/100 -> 12.6 | I6: =(G$22/C$22)*H6 -> 13.179107
A7: Supermarket1960 | B7: 1961 | C7: 1990 | D7: =(B7+C7)/2 -> 1975.5 | E7: =dist_calculations!E$24 -> 38 | F7: 14 | G7: 20 | H7: =E7*F7*G7/100 -> 106.4 | I7: =(G$24/C$24)*H7 -> 61.284797
A8: Convenience1975 | B8: 1975 | C8: 2010 | D8: =(B8+C8)/2 -> 1992.5 | E8: =dist_calculations!E$26 -> 11 | F8: 8 | G8: 26 | H8: =E8*F8*G8/100 -> 22.88 | I8: =(G$27/C$27)*H8 -> 19.732543
A9: PetrolStation1975 | B9: 1975 | C9: 2010 | D9: =(B9+C9)/2 -> 1992.5 | E9: 18 | F9: 32 | G9: 10 | H9: =E9*F9*G9/100 -> 57.6 | I9: =(G$27/C$27)*H9 -> 49.676332
A10: Supermarket1980 | B10: 1985 | C10: 2010 | D10: =(B10+C10)/2 -> 1997.5 | E10: =dist_calculations!E$29 -> 10 | F10: 42 | G10: 20 | H10: =E10*F10*G10/100 -> 84 | I10: =(G$28/C$28)*H10 -> 80.698472
A11: SupermarketSmall1990 | B11: 1990 | C11: 2010 | D11: =(B11+C11)/2 -> 2000 | E11: =dist_calculations!E$28 -> 15 | F11: =42/3 -> 14 | G11: 20 | H11: =E11*F11*G11/100 -> 42 | I11: =(G$29/C$29)*H11 -> 42
B13: Timeline
A14: Midpoint industry | B14: Year | C14: Current eff. Consumption | D14: Source consumption | E14: Source (interpolated) | F14: Source (relative) | G14: Adj. Consumption | H14: New consumption | I14: %
B16: 1810 | D16: 0
A17: Grocers1810 | B17: 1835 | C17: =H2 -> 10.56 | E17: =_xlfn.FORECAST.LINEAR(B17,D$16:D$23,B$16:B$23) -> 2748.2143 | F17: =(E17/D$29)*100 -> 6.4131465 | G17: =(F17/F$29)*C$29 -> 13.241865 | H17: =I2 -> 13.241865 | I17: =(H17/C17)*100 -> 125.39645
A18: Grocer1860 | B18: 1880 | C18: =H3 -> 36.96 | E18: =_xlfn.FORECAST.LINEAR(B18,D$16:D$23,B$16:B$23) -> 7695 | F18: =(E18/D$29)*100 -> 17.95681 | G18: =(F18/F$29)*C$29 -> 37.077222 | H18: =I3 -> 37.077222 | I18: =(H18/C18)*100 -> 100.31716
A19: Grocer1900 | B19: 1923 | C19: =H4 -> 118.8 | E19: =_xlfn.FORECAST.LINEAR(B19,D$16:D$23,B$16:B$23) -> 12421.929 | F19: =(E19/D$29)*100 -> 28.987422 | G19: =(F19/F$29)*C$29 -> 59.85323 | H19: =I4 -> 59.85323 | I19: =(H19/C19)*100 -> 50.381506
B20: 1935 | C20: =H4 -> 118.8 | E20: =_xlfn.FORECAST.LINEAR(B20,D$16:D$23,B$16:B$23) -> 13741.071 | F20: =(E20/D$29)*100 -> 32.065733 | G20: =(F20/F$29)*C$29 -> 66.209325 | H20: =I4 -> 59.85323 | I20: =(H20/C20)*100 -> 50.381506
A21: Grocer1945 | B21: 1960 | C21: =H5+H6 -> 75.96 | E21: =_xlfn.FORECAST.LINEAR(B21,D$16:D$23,B$16:B$23) -> 16489.286 | F21: =(E21/D$29)*100 -> 38.478879 | G21: =(F21/F$29)*C$29 -> 79.45119 | H21: =I5+I6 -> 79.45119 | I21: =(H21/C21)*100 -> 104.59609
A22: Supermarket1950 | B22: 1960 | C22: =H5+H6 -> 75.96 | E22: =_xlfn.FORECAST.LINEAR(B22,D$16:D$23,B$16:B$23) -> 16489.286 | F22: =(E22/D$29)*100 -> 38.478879 | G22: =(F22/F$29)*C$29 -> 79.45119 | H22: =I5+I6 -> 79.45119 | I22: =(H22/C22)*100 -> 104.59609
B23: 1970 | C23: =H5+H6+H7 -> 182.36 | D23: =sources_consumption!D30 -> 17588.571 | F23: =(D23/D$29)*100 -> 41.044138 | G23: =(F23/F$29)*C$29 -> 84.747936 | H23: =I6+I7 -> 74.463905 | I23: =(H23/C23)*100 -> 40.833464
A24: Supermarket1960 | B24: 1975 | C24: =H5+H6+H7 -> 182.36 | E24: =_xlfn.FORECAST.LINEAR(B24,D$23:D$29,B$23:B$29) -> 21799.28 | F24: =(E24/D$29)*100 -> 50.870115 | G24: =(F24/F$29)*C$29 -> 105.03661 | H24: =I8+I9 -> 69.408875 | I24: =(H24/C24)*100 -> 38.061458
B25: 1980 | C25: =H6+H7+H8+H9 -> 199.48 | E25: =_xlfn.FORECAST.LINEAR(B25,D$23:D$29,B$23:B$29) -> 26009.988 | F25: =(E25/D$29)*100 -> 60.696092 | G25: =(F25/F$29)*C$29 -> 125.32529 | H25: =I8+I9 -> 69.408875 | I25: =(H25/C25)*100 -> 34.794904
B26: 1982 | C26: =H7+H8+H9 -> 186.88 | E26: =_xlfn.FORECAST.LINEAR(B26,D$23:D$29,B$23:B$29) -> 27694.272 | F26: =(E26/D$29)*100 -> 64.626483 | G26: =(F26/F$29)*C$29 -> 133.44076 | H26: =I7+I8+I9 -> 130.69367 | I26: =(H26/C26)*100 -> 69.934542
